Workbook

Sheet Data
A1: 3 | B1: apple | C1: 1 | D1: 45000 | E1: 1 | F1: one | G1: 2 | H1: 1 | I1: 0 | J1: Region | K1: Sales | L1: Year
A2: -1.5 | B2: Banana | C2: 2 | D2: 45001.5 | E2: 10 | F2: ten | G2: 1 | H2: 3 | I2: 1 | J2: North | K2: 120 | L2: 2021
A3: 7 | B3: cherry | C3: =TRUE() -> TRUE | D3: 44927 | E3: 100 | F3: hundred | G3: 0 | H3: 1 | I3: 4 | J3: South | K3: 80 | L3: 2021
A4: 0 | B4: apple pie | D4: 36526 | E4: 1000 | F4: thousand | J4: North | K4: 45 | L4: 2022
A5: 12.25 | C5: 5 | D5: 1 | E5: 10000 | F5: ten thousand | J5: East | K5: 200 | L5: 2022
A6: 4 | B6: Date | C6: x | D6: 60 | J6: South | K6: 95 | L6: 2023
A7: 4 | B7: egg | C7: 7.5 | D7: 61 | J7: North | K7: 60 | L7: 2023
A8: 9 | B8: fig | C8: =FALSE() -> FALSE | D8: 2958465
A9: 2.5 | B9: grape | C9: 9 | D9: 40000.25
A10: 100 | B10: kiwi | C10: -3 | D10: 0.75

Sheet F
A1: =-2^2 -> 4 | B1: =-2^2
A2: =2^3^2 -> 64 | B2: =2^3^2
A3: =1+2*3-4/8 -> 6.5 | B3: =1+2*3-4/8
A4: =50%*10 -> 5 | B4: =50%*10
A5: ="3"+1 -> 4 | B5: ="3"+1
A6: =TRUE()+TRUE() -> 2 | B6: =TRUE+TRUE
A7: ="a"&1.5&TRUE() -> a1.51 | B7: ="a"&1.5&TRUE
A8: =0.1+0.2=0.3 -> TRUE | B8: =0.1+0.2=0.3
A9: =1/0 -> #DIV/0! | B9: =1/0
A10: ="abc"*2 -> #VALUE! | B10: ="abc"*2
A11: ="a"<"B" -> TRUE | B11: ="a"<"B"
A12: =1<"0" -> TRUE | B12: =1<"0"
A13: =Data!C4=0 -> TRUE | B13: =Data!C4=0
A14: =Data!C4="" -> TRUE | B14: =Data!C4=""
A15: =2^0.5 -> 1.4142136 | B15: =2^0.5
A16: =-Data!A2 -> 1.5 | B16: =-Data!A2
A17: =Data!A1:A3*2 -> #VALUE! | B17: =Data!A1:A3*2
A18: =(Data!A1+Data!A3)/2 -> 5 | B18: =(Data!A1+Data!A3)/2
A19: =SUM(Data!A1:A10) -> 140.25 | B19: =SUM(Data!A1:A10)
A20: =SUM(Data!C1:C10) -> 20.5 | B20: =SUM(Data!C1:C10)
A21: =SUM(1,"2",TRUE()) -> #VALUE! | B21: =SUM(1,"2",TRUE)
A22: =SUM(Data!A:A) -> 140.25 | B22: =SUM(Data!A:A)
A23: =PRODUCT(Data!A1:A3) -> -31.5 | B23: =PRODUCT(Data!A1:A3)
A24: =SUMSQ(Data!A1:A3) -> 60.25 | B24: =SUMSQ(Data!A1:A3)
A25: =AVERAGE(Data!A1:A10) -> 14.025 | B25: =AVERAGE(Data!A1:A10)
A26: =AVERAGE(Data!C1:C10) -> 2.9285714 | B26: =AVERAGE(Data!C1:C10)
A27: =AVERAGEA(Data!C1:C10) -> 2.2777778 | B27: =AVERAGEA(Data!C1:C10)
A28: =MIN(Data!A1:A10) -> -1.5 | B28: =MIN(Data!A1:A10)
A29: =MAX(Data!A1:A10) -> 100 | B29: =MAX(Data!A1:A10)
A30: =MINA(Data!C1:C10) -> -3 | B30: =MINA(Data!C1:C10)
A31: =MAXA(Data!C1:C10) -> 9 | B31: =MAXA(Data!C1:C10)
A32: =COUNT(Data!C1:C10) -> 7 | B32: =COUNT(Data!C1:C10)
A33: =COUNTA(Data!C1:C10) -> 9 | B33: =COUNTA(Data!C1:C10)
A34: =COUNTBLANK(Data!C1:C10) -> 1 | B34: =COUNTBLANK(Data!C1:C10)
A35: =COUNT(Data!B1:B10) -> 0 | B35: =COUNT(Data!B1:B10)
A36: =COUNTA(Data!B1:B10) -> 9 | B36: =COUNTA(Data!B1:B10)
A37: =SUMIF(Data!A1:A10,">3") -> 136.25 | B37: =SUMIF(Data!A1:A10,">3")
A38: =SUMIF(Data!B1:B10,"apple*",Data!A1:A10) -> 3 | B38: =SUMIF(Data!B1:B10,"apple*",Data!A1:A10)
A39: =SUMIF(Data!A1:A10,"<>4") -> 132.25 | B39: =SUMIF(Data!A1:A10,"<>4")
A40: =COUNTIF(Data!B1:B10,"?pple*") -> 2 | B40: =COUNTIF(Data!B1:B10,"?pple*")
...
